`pytest`会在命令执行的根目录下生成一个`.pytest_cache`文件夹，这个行为是由自带的`cacheprovider`插件来实现的；

> 注意：
> 
> `pytest`默认在命令执行的根目录中生成`.pytest_cache`文件夹，我们也可以通过在`pytest.ini`中配置`cache_dir`选项来自定义缓存的目录，它可以是相对路径，也可以是绝对路径；
> 
> 相对路径指的是相对于`pytest.ini`文件所在的目录；例如，我们把这一章的缓存和源码放在一起：
> 
> 在`src/chapter-12/pytest.ini`中添加如下配置：
> 
> ```ini
> [pytest]
> cache_dir = .pytest-cache
> ```
> 
> 这样，即使我们在项目的根目录下执行`src/chapter-12/`中的用例，也只会在`~/pytest-chinese-doc/src/chapter-12/.pytest_cache`中生成缓存，而不再是`~/pytest-chinese-doc/.pytest_cache`中；
> 
> ```bash
> ~/pytest-chinese-doc (5.1.3) 
> λ pipenv run pytest src/chapter-12
> ```

## `cacheprovider`插件
在介绍这个插件之前，我们先看一个简单例子：

```python
# src/chapter-12/test_failed.py

import pytest


@pytest.mark.parametrize('num', [1, 2])
def test_failed(num):
    assert num == 1


# src\chapter-12\test_pass.py

def test_pass():
    assert 1
```

我们有两个简单的测试模块，首先我们来执行一下对它们的测试：

```bash
λ pipenv run pytest -q src/chapter-12/
.F.                                                                [100%] 
=============================== FAILURES ================================ 
____________________________ test_failed[2] _____________________________

num = 2

    @pytest.mark.parametrize('num', [1, 2])
    def test_failed(num):
>       assert num == 1
E       assert 2 == 1

src\chapter-12\test_failed.py:27: AssertionError
1 failed, 2 passed in 0.08s
```

可以看到一共收集到**三个**测试用例，其中有一个失败，另外两个成功的，并且两个执行成功的用例分属不同的测试模块；

同时，`pytest`也在`src/chapter-12/`的目录下生成缓存文件夹（`.pytest_cache`），具体的目录结构如下所示：

```bash
src
├───chapter-12
│   │   pytest.ini  # 配置了 cache_dir = .pytest-cache
│   │   test_failed.py
│   │   test_pass.py
│   │
│   └───.pytest-cache
│       │   .gitignore
│       │   CACHEDIR.TAG
│       │   README.md
│       │
│       └───v
│           └───cache
│                   lastfailed
│                   nodeids
│                   stepwise
```

现在，我们就结合上面的组织结构，具体介绍一下`cacheprovider`插件的功能；

### `--lf, --last-failed`：只执行上一轮失败的用例
缓存中的`lastfailed`文件记录了上次失败的用例`ID`，我们可以通过一下`--cache-show`命令查看它的内容：

> `--cache-show`命令也是`cacheprovider`提供的新功能，它不会导致任何用例的执行；

```bash
λ pipenv run pytest src/chapter-12/ -q --cache-show 'lastfailed'
cachedir: D:\Personal Files\Projects\pytest-chinese-doc\src\chapter-12\.pytest-cache
--------------------- cache values for 'lastfailed' --------------------- 
cache\lastfailed contains:
  {'test_failed.py::test_failed[2]': True}

no tests ran in 0.01s
```

我们可以看到，它记录了一个用例，为上次失败的测试用例的`ID`：`test_failed.py::test_failed[2]`；

下次执行时，当我们使用`--lf`选项，`pytest`在收集阶段只会选择这个失败的用例，而忽略其它的：

```bash
λ pipenv run pytest --lf --collect-only src/chapter-12/
========================== test session starts ==========================
platform win32 -- Python 3.7.3, pytest-5.1.3, py-1.8.0, pluggy-0.13.0
cachedir: .pytest-cache
rootdir: D:\Personal Files\Projects\pytest-chinese-doc\src\chapter-12, inifile: pytest.ini
collected 2 items / 1 deselected / 1 selected
<Module test_failed.py>
  <Function test_failed[2]>
run-last-failure: rerun previous 1 failure (skipped 2 files)

========================= 1 deselected in 0.02s =========================
```

我们仔细观察一下上面的回显，有一句话可能会让我们有点困惑：`collected 2 items / 1 deselected / 1 selected`，可我们明明有三个用例，怎么会只收集到两个呢？

实际上，`--lf`复写了用例收集阶段的两个钩子方法：`pytest_ignore_collect(path, config)`和`pytest_collection_modifyitems(session, config, items)`；

我们来先看看`pytest_ignore_collect(path, config)`，如果它的结果返回`True`，就忽略`path`路径中的用例；

```python
# _pytest/cacheprovider.py

    def last_failed_paths(self):
        """Returns a set with all Paths()s of the previously failed nodeids (cached).
        """
        try:
            return self._last_failed_paths
        except AttributeError:
            rootpath = Path(self.config.rootdir)
            result = {rootpath / nodeid.split("::")[0] for nodeid in self.lastfailed}
            result = {x for x in result if x.exists()}
            self._last_failed_paths = result
            return result

    def pytest_ignore_collect(self, path):
        """
        Ignore this file path if we are in --lf mode and it is not in the list of
        previously failed files.
        """
        if self.active and self.config.getoption("lf") and path.isfile():
            last_failed_paths = self.last_failed_paths()
            if last_failed_paths:
                skip_it = Path(path) not in self.last_failed_paths()
                if skip_it:
                    self._skipped_files += 1
                return skip_it
```

可以看到，如果当前收集的文件，不在上一次失败的路径集合内，就会忽略这个文件，所以这次执行就不会到`test_pass.py`中收集用例了，故而只收集到两个用例；并且`pytest.ini`也在忽略的名单上，所以实际上是跳过两个文件：`(skipped 2 files)`；

至于`pytest_collection_modifyitems(session, config, items)`钩子方法，我们在下一节和`--ff`命令一起看；

### `--ff, --failed-first`：先执行上一轮失败的用例，再执行剩余的
我们先通过实践看看这个命令的效果，再去分析它的实现：

```bash
λ pipenv run pytest --collect-only -s --ff src/chapter-12/
========================== test session starts ========================== 
platform win32 -- Python 3.7.3, pytest-5.1.3, py-1.8.0, pluggy-0.13.0
cachedir: .pytest-cache
rootdir: D:\Personal Files\Projects\pytest-chinese-doc\src\chapter-12, inifile: pytest.ini
collected 3 items
<Module test_failed.py>
  <Function test_failed[2]>
  <Function test_failed[1]>
<Module test_pass.py>
  <Function test_pass>
run-last-failure: rerun previous 1 failure first

========================= no tests ran in 0.02s =========================
```

我们可以看到一共收集到三个测试用例，和正常的收集顺序相比，上一轮失败的`test_failed.py::test_failed[2]`用例在最前面，将优先执行；

实际上，`-ff`只复写了钩子方法：`pytest_collection_modifyitems(session, config, items)`，它可以过滤或者重新排序收集到的用例：

```python
# _pytest/cacheprovider.py

    def pytest_collection_modifyitems(self, session, config, items):
        ...

                if self.config.getoption("lf"):
                    items[:] = previously_failed
                    config.hook.pytest_deselected(items=previously_passed)
                else:  # --failedfirst
                    items[:] = previously_failed + previously_passed

        ...
```

可以看到，如果使用的是`lf`，就把之前成功的用例状态置为`deselected`，这轮执行就会忽略它们；如果使用的是`-ff`，只是将之前失败的用例，顺序调到前面；

另外，我们也可以看到`lf`的优先级要高于`ff`，所以它们同时使用的话，`ff`是不起作用的；

### `--nf, --new-first`：先执行新加的或修改的用例，在执行其它的
缓存中的`nodeids`文件记录了上一轮执行的所有的用例：

```bash
λ pipenv run pytest src/chapter-12 --cache-show 'nodeids'
========================== test session starts ==========================
platform win32 -- Python 3.7.3, pytest-5.1.3, py-1.8.0, pluggy-0.13.0
cachedir: .pytest-cache
rootdir: D:\Personal Files\Projects\pytest-chinese-doc\src\chapter-12, inifile: pytest.ini
cachedir: D:\Personal Files\Projects\pytest-chinese-doc\src\chapter-12\.pytest-cache
---------------------- cache values for 'nodeids' -----------------------
cache\nodeids contains:
  ['test_failed.py::test_failed[1]',
   'test_failed.py::test_failed[2]',
   'test_pass.py::test_pass']

========================= no tests ran in 0.01s =========================
```

我们看到上一轮共执行了三个测试用例；

现在我们在`test_pass.py`中新加一个用例，并修改一下`test_failed.py`文件中的用例（但是不添加新用例）：

```python
# src\chapter-12\test_pass.py

def test_pass():
    assert 1


def test_new_pass():
    assert 1
```

现在我们再来执行一下收集命令：

```bash
λ pipenv run pytest --collect-only -s --nf src/chapter-12/
========================== test session starts ==========================
platform win32 -- Python 3.7.3, pytest-5.1.3, py-1.8.0, pluggy-0.13.0
cachedir: .pytest-cache
rootdir: D:\Personal Files\Projects\pytest-chinese-doc\src\chapter-12, inifile: pytest.ini
collected 4 items
<Module test_pass.py>
  <Function test_new_pass>
<Module test_failed.py>
  <Function test_failed[1]>
  <Function test_failed[2]>
<Module test_pass.py>
  <Function test_pass>

========================= no tests ran in 0.03s =========================
```

可以看到，新加的用例顺序在最前面，其次修改过的测试用例紧接其后，最后才是旧的用例；这个行为在源码中有所体现：

```python
# _pytest/cacheprovider.py

    def pytest_collection_modifyitems(self, session, config, items):
        if self.active:
            new_items = OrderedDict()
            other_items = OrderedDict()
            for item in items:
                if item.nodeid not in self.cached_nodeids:
                    new_items[item.nodeid] = item
                else:
                    other_items[item.nodeid] = item

            items[:] = self._get_increasing_order(
                new_items.values()
            ) + self._get_increasing_order(other_items.values())
        self.cached_nodeids = [x.nodeid for x in items if isinstance(x, pytest.Item)]

    def _get_increasing_order(self, items):
        return sorted(items, key=lambda item: item.fspath.mtime(), reverse=True)
```

`item.fspath.mtime()`代表用例所在文件的最后修改时间，`reverse=True`表明是倒序排列；

`items[:] = self._get_increasing_order(new_items.values()) + self._get_increasing_order(other_items.values())`保证新加的用例永远在最前面；

`--cache-clear`：先清除所有缓存，再执行用例
直接看源码：

```python
# _pytest/cacheprovider.py

class Cache:

    ... 

    @classmethod
    def for_config(cls, config):
        cachedir = cls.cache_dir_from_config(config)
        if config.getoption("cacheclear") and cachedir.exists():
            rm_rf(cachedir)
            cachedir.mkdir()
        return cls(cachedir, config)
```

可以看到，它会先把已有的缓存文件夹删除（`rm_rf(cachedir)`），再创建一个空的同名文件夹（`cachedir.mkdir()`），这样会导致上述的功能失效，所以一般不使用这个命令；

### 如果上一轮没有失败的用例
现在，我们清除缓存，再执行`test_pass.py`模块（它的用例都是能测试成功的）：

```bash
λ pipenv run pytest --cache-clear -q -s src/chapter-12/test_pass.py
.
1 passed in 0.01s
```

这时候我们再去看一下缓存目录：

```bash
.pytest-cache
└───v
    └───cache
            nodeids
            stepwise
```

是不是少了什么？对！因为没有失败的用例，所以不会生成`lastfailed`文件，那么这个时候在使用`--lf`和`--ff`会发生什么呢？我们来试试：

```bash
luyao@NJ-LUYAO-T460 /d/Personal Files/Projects/pytest-chinese-doc (5.1.3) 
λ pipenv run pytest -q -s --lf src/chapter-12/test_pass.py
.
1 passed in 0.01s

luyao@NJ-LUYAO-T460 /d/Personal Files/Projects/pytest-chinese-doc (5.1.3) 
λ pipenv run pytest -q -s --ff src/chapter-12/test_pass.py
.
1 passed in 0.02s
```

可以看到，它们没有实施任何影响；为什么会这样？我们去源码里找一下答案吧；

```python
# _pytest/cacheprovider.py

class LFPlugin:
    """ Plugin which implements the --lf (run last-failing) option """

    def __init__(self, config):
        ...
        self.lastfailed = config.cache.get("cache/lastfailed", {})
        ...

    def pytest_collection_modifyitems(self, session, config, items):
        ...

        if self.lastfailed:

            ...

        else:
            self._report_status = "no previously failed tests, "
            if self.config.getoption("last_failed_no_failures") == "none":
                self._report_status += "deselecting all items."
                config.hook.pytest_deselected(items=items)
                items[:] = []
            else:
                self._report_status += "not deselecting items."
```

可以看到，当`self.lastfailed`判断失败时，如果我们指定了`last_failed_no_failures`选项为`none`，`pytest`会忽略所有的用例（`items[:] = []`），否则不做任何修改（和没加`--lf`或`--ff`一样），而判断`self.lastfailed`的依据是就是`lastfailed`文件；

继续看看，我们会学习到一个新的命令行选项：

```python
# _pytest/cacheprovider.py

    group.addoption(
            "--lfnf",
            "--last-failed-no-failures",
            action="store",
            dest="last_failed_no_failures",
            choices=("all", "none"),
            default="all",
            help="which tests to run with no previously (known) failures.",
        )
```

来试试吧：

```bash
λ pipenv run pytest -q -s --ff --lfnf none src/chapter-12/test_pass.py

1 deselected in 0.01s

λ pipenv run pytest -q -s --ff --lfnf all src/chapter-12/test_pass.py
.
1 passed in 0.01s
```

> 注意：
> 
> 它的实参只支持`choices=("all", "none")`；
